[Sat Oct 06 14:06:03 2012] [error] [client 171.65.80.27] mod_wsgi (pid=1051): Exception occurred processing WSGI script '/home/httpd/users/niru/neurosite/main/django.wsgi'.
[Sat Oct 06 14:06:03 2012] [error] [client 171.65.80.27] Traceback (most recent call last):
[Sat Oct 06 14:06:03 2012] [error] [client 171.65.80.27]   File "/usr/local/virt_python/lib/python2.7/site-packages/django/core/handlers/wsgi.py", line 241, in __call__
[Sat Oct 06 14:06:03 2012] [error] [client 171.65.80.27]     response = self.get_response(request)
[Sat Oct 06 14:06:03 2012] [error] [client 171.65.80.27]   File "/usr/local/virt_python/lib/python2.7/site-packages/django/core/handlers/base.py", line 179, in get_response
[Sat Oct 06 14:06:03 2012] [error] [client 171.65.80.27]     response = self.handle_uncaught_exception(request, resolver, sys.exc_info())
[Sat Oct 06 14:06:03 2012] [error] [client 171.65.80.27]   File "/usr/local/virt_python/lib/python2.7/site-packages/django/core/handlers/base.py", line 221, in handle_uncaught_exception
[Sat Oct 06 14:06:03 2012] [error] [client 171.65.80.27]     return debug.technical_500_response(request, *exc_info)
[Sat Oct 06 14:06:03 2012] [error] [client 171.65.80.27]   File "/usr/local/virt_python/lib/python2.7/site-packages/django/views/debug.py", line 66, in technical_500_response
[Sat Oct 06 14:06:03 2012] [error] [client 171.65.80.27]     html = reporter.get_traceback_html()
[Sat Oct 06 14:06:03 2012] [error] [client 171.65.80.27]   File "/usr/local/virt_python/lib/python2.7/site-packages/django/views/debug.py", line 287, in get_traceback_html
[Sat Oct 06 14:06:03 2012] [error] [client 171.65.80.27]     return t.render(c)
[Sat Oct 06 14:06:03 2012] [error] [client 171.65.80.27]   File "/usr/local/virt_python/lib/python2.7/site-packages/django/template/base.py", line 140, in render
[Sat Oct 06 14:06:03 2012] [error] [client 171.65.80.27]     return self._render(context)
[Sat Oct 06 14:06:03 2012] [error] [client 171.65.80.27]   File "/usr/local/virt_python/lib/python2.7/site-packages/django/template/base.py", line 134, in _render
[Sat Oct 06 14:06:03 2012] [error] [client 171.65.80.27]     return self.nodelist.render(context)
[Sat Oct 06 14:06:03 2012] [error] [client 171.65.80.27]   File "/usr/local/virt_python/lib/python2.7/site-packages/django/template/base.py", line 823, in render
[Sat Oct 06 14:06:03 2012] [error] [client 171.65.80.27]     bit = self.render_node(node, context)
[Sat Oct 06 14:06:03 2012] [error] [client 171.65.80.27]   File "/usr/local/virt_python/lib/python2.7/site-packages/django/template/debug.py", line 74, in render_node
[Sat Oct 06 14:06:03 2012] [error] [client 171.65.80.27]     return node.render(context)
[Sat Oct 06 14:06:03 2012] [error] [client 171.65.80.27]   File "/usr/local/virt_python/lib/python2.7/site-packages/django/template/debug.py", line 84, in render
[Sat Oct 06 14:06:03 2012] [error] [client 171.65.80.27]     output = self.filter_expression.resolve(context)
[Sat Oct 06 14:06:03 2012] [error] [client 171.65.80.27]   File "/usr/local/virt_python/lib/python2.7/site-packages/django/template/base.py", line 599, in resolve
[Sat Oct 06 14:06:03 2012] [error] [client 171.65.80.27]     new_obj = func(obj, *arg_vals)
[Sat Oct 06 14:06:03 2012] [error] [client 171.65.80.27]   File "/usr/local/virt_python/lib/python2.7/site-packages/django/template/defaultfilters.py", line 718, in date
[Sat Oct 06 14:06:03 2012] [error] [client 171.65.80.27]     return format(value, arg)
[Sat Oct 06 14:06:03 2012] [error] [client 171.65.80.27]   File "/usr/local/virt_python/lib/python2.7/site-packages/django/utils/dateformat.py", line 310, in format
[Sat Oct 06 14:06:03 2012] [error] [client 171.65.80.27]     return df.format(format_string)
[Sat Oct 06 14:06:03 2012] [error] [client 171.65.80.27]   File "/usr/local/virt_python/lib/python2.7/site-packages/django/utils/dateformat.py", line 33, in format
[Sat Oct 06 14:06:03 2012] [error] [client 171.65.80.27]     pieces.append(force_unicode(getattr(self, piece)()))
[Sat Oct 06 14:06:03 2012] [error] [client 171.65.80.27]   File "/usr/local/virt_python/lib/python2.7/site-packages/django/utils/dateformat.py", line 214, in r
[Sat Oct 06 14:06:03 2012] [error] [client 171.65.80.27]     return self.format('D, j M Y H:i:s O')
[Sat Oct 06 14:06:03 2012] [error] [client 171.65.80.27]   File "/usr/local/virt_python/lib/python2.7/site-packages/django/utils/dateformat.py", line 33, in format
[Sat Oct 06 14:06:03 2012] [error] [client 171.65.80.27]     pieces.append(force_unicode(getattr(self, piece)()))
[Sat Oct 06 14:06:03 2012] [error] [client 171.65.80.27]   File "/usr/local/virt_python/lib/python2.7/site-packages/django/utils/encoding.py", line 71, in force_unicode
[Sat Oct 06 14:06:03 2012] [error] [client 171.65.80.27]     s = unicode(s)
[Sat Oct 06 14:06:03 2012] [error] [client 171.65.80.27]   File "/usr/local/virt_python/lib/python2.7/site-packages/django/utils/functional.py", line 121, in __unicode_cast
[Sat Oct 06 14:06:03 2012] [error] [client 171.65.80.27]     return func(*self.__args, **self.__kw)
[Sat Oct 06 14:06:03 2012] [error] [client 171.65.80.27]   File "/usr/local/virt_python/lib/python2.7/site-packages/django/utils/translation/__init__.py", line 86, in ugettext
[Sat Oct 06 14:06:03 2012] [error] [client 171.65.80.27]     return _trans.ugettext(message)
[Sat Oct 06 14:06:03 2012] [error] [client 171.65.80.27]   File "/usr/local/virt_python/lib/python2.7/site-packages/django/utils/translation/trans_real.py", line 278, in ugettext
[Sat Oct 06 14:06:03 2012] [error] [client 171.65.80.27]     return do_translate(message, 'ugettext')
[Sat Oct 06 14:06:03 2012] [error] [client 171.65.80.27]   File "/usr/local/virt_python/lib/python2.7/site-packages/django/utils/translation/trans_real.py", line 268, in do_translate
[Sat Oct 06 14:06:03 2012] [error] [client 171.65.80.27]     _default = translation(settings.LANGUAGE_CODE)
[Sat Oct 06 14:06:03 2012] [error] [client 171.65.80.27]   File "/usr/local/virt_python/lib/python2.7/site-packages/django/utils/translation/trans_real.py", line 183, in translation
[Sat Oct 06 14:06:03 2012] [error] [client 171.65.80.27]     default_translation = _fetch(settings.LANGUAGE_CODE)
[Sat Oct 06 14:06:03 2012] [error] [client 171.65.80.27]   File "/usr/local/virt_python/lib/python2.7/site-packages/django/utils/translation/trans_real.py", line 160, in _fetch
[Sat Oct 06 14:06:03 2012] [error] [client 171.65.80.27]     app = import_module(appname)
[Sat Oct 06 14:06:03 2012] [error] [client 171.65.80.27]   File "/usr/local/virt_python/lib/python2.7/site-packages/django/utils/importlib.py", line 35, in import_module
[Sat Oct 06 14:06:03 2012] [error] [client 171.65.80.27]     __import__(name)
[Sat Oct 06 14:06:03 2012] [error] [client 171.65.80.27] ImportError: No module named main
